<?xml version="1.0" ?>
<robot name="Omnitrak" xmlns:xacro="http://www.ros.org/wiki/xacro"> 

<xacro:include filename="$(find omnitrak)/urdf/materials.xacro" />
<xacro:include filename="$(find omnitrak)/urdf/omnitrak.trans" />
<xacro:include filename="$(find omnitrak)/urdf/omnitrak.gazebo" />
<link name="base_link">
  <inertial>
    <origin xyz="0.0033509972469905726 -0.07983989479510532 -0.16272398338715227" rpy="0 0 0"/>
    <mass value="3.756754485407772"/>
    <inertia ixx="0.060392" iyy="0.102325" izz="0.143008" ixy="0.0" iyz="0.0" ixz="0.0"/>
  </inertial>
  <visual>
    <origin xyz="0 0 0" rpy="0 0 0"/>
    <geometry>
      <mesh filename="package://omnitrak/meshes/base_link.stl" scale="0.001 0.001 0.001"/>
    </geometry>
    <material name="silver"/>
  </visual>
  <collision>
    <origin xyz="0 0 0" rpy="0 0 0"/>
    <geometry>
      <mesh filename="package://omnitrak/meshes/base_link.stl" scale="0.001 0.001 0.001"/>
    </geometry>
  </collision>
</link>

<link name="perfillateral1_1">
  <inertial>
    <origin xyz="-2.7530149835156004e-09 0.015003770494463622 1.2883848897471406e-07" rpy="0 0 0"/>
    <mass value="0.9125243020557182"/>
    <inertia ixx="0.000385" iyy="0.022766" izz="0.022544" ixy="0.0" iyz="0.0" ixz="0.0"/>
  </inertial>
  <visual>
    <origin xyz="-0.003351 -0.081985 0.083653" rpy="0 0 0"/>
    <geometry>
      <mesh filename="package://omnitrak/meshes/perfillateral1_1.stl" scale="0.001 0.001 0.001"/>
    </geometry>
    <material name="silver"/>
  </visual>
  <collision>
    <origin xyz="-0.003351 -0.081985 0.083653" rpy="0 0 0"/>
    <geometry>
      <mesh filename="package://omnitrak/meshes/perfillateral1_1.stl" scale="0.001 0.001 0.001"/>
    </geometry>
  </collision>
</link>

<link name="perfillateral2_1">
  <inertial>
    <origin xyz="-2.7530217328909645e-09 -0.014996213251006835 1.2883848980738133e-07" rpy="0 0 0"/>
    <mass value="0.9125243020557182"/>
    <inertia ixx="0.000385" iyy="0.022766" izz="0.022544" ixy="0.0" iyz="0.0" ixz="0.0"/>
  </inertial>
  <visual>
    <origin xyz="-0.003351 0.241665 0.083653" rpy="0 0 0"/>
    <geometry>
      <mesh filename="package://omnitrak/meshes/perfillateral2_1.stl" scale="0.001 0.001 0.001"/>
    </geometry>
    <material name="silver"/>
  </visual>
  <collision>
    <origin xyz="-0.003351 0.241665 0.083653" rpy="0 0 0"/>
    <geometry>
      <mesh filename="package://omnitrak/meshes/perfillateral2_1.stl" scale="0.001 0.001 0.001"/>
    </geometry>
  </collision>
</link>

<link name="tapabase1_1">
  <inertial>
    <origin xyz="-0.07352089009695101 0.26363900951257213 0.2742774060012232" rpy="0 0 0"/>
    <mass value="0.0826803513797181"/>
    <inertia ixx="5.4e-05" iyy="5.4e-05" izz="5.1e-05" ixy="-3e-06" iyz="-2e-06" ixz="2e-06"/>
  </inertial>
  <visual>
    <origin xyz="-0.371098 0.51333 0.358754" rpy="0 0 0"/>
    <geometry>
      <mesh filename="package://omnitrak/meshes/tapabase1_1.stl" scale="0.001 0.001 0.001"/>
    </geometry>
    <material name="silver"/>
  </visual>
  <collision>
    <origin xyz="-0.371098 0.51333 0.358754" rpy="0 0 0"/>
    <geometry>
      <mesh filename="package://omnitrak/meshes/tapabase1_1.stl" scale="0.001 0.001 0.001"/>
    </geometry>
  </collision>
</link>

<link name="tapabase2_1">
  <inertial>
    <origin xyz="0.6619731310665693 -0.10395882026630716 -0.2759245939987778" rpy="0 0 0"/>
    <mass value="0.0826803513797181"/>
    <inertia ixx="5.4e-05" iyy="5.4e-05" izz="5.1e-05" ixy="3e-06" iyz="2e-06" ixz="2e-06"/>
  </inertial>
  <visual>
    <origin xyz="0.364396 -0.19397 -0.191448" rpy="0 0 0"/>
    <geometry>
      <mesh filename="package://omnitrak/meshes/tapabase2_1.stl" scale="0.001 0.001 0.001"/>
    </geometry>
    <material name="silver"/>
  </visual>
  <collision>
    <origin xyz="0.364396 -0.19397 -0.191448" rpy="0 0 0"/>
    <geometry>
      <mesh filename="package://omnitrak/meshes/tapabase2_1.stl" scale="0.001 0.001 0.001"/>
    </geometry>
  </collision>
</link>

<link name="tapabase3_1">
  <inertial>
    <origin xyz="0.07352088459091499 -0.10395879910278584 0.2675754060012222" rpy="0 0 0"/>
    <mass value="0.0826803513797181"/>
    <inertia ixx="5.4e-05" iyy="5.4e-05" izz="5.1e-05" ixy="-3e-06" iyz="2e-06" ixz="-2e-06"/>
  </inertial>
  <visual>
    <origin xyz="0.364396 -0.19397 0.352052" rpy="0 0 0"/>
    <geometry>
      <mesh filename="package://omnitrak/meshes/tapabase3_1.stl" scale="0.001 0.001 0.001"/>
    </geometry>
    <material name="silver"/>
  </visual>
  <collision>
    <origin xyz="0.364396 -0.19397 0.352052" rpy="0 0 0"/>
    <geometry>
      <mesh filename="package://omnitrak/meshes/tapabase3_1.stl" scale="0.001 0.001 0.001"/>
    </geometry>
  </collision>
</link>

<link name="tapabase4_1">
  <inertial>
    <origin xyz="-0.6619731365726056 0.2636390306760915 -0.2692225939987769" rpy="0 0 0"/>
    <mass value="0.0826803513797181"/>
    <inertia ixx="5.4e-05" iyy="5.4e-05" izz="5.1e-05" ixy="3e-06" iyz="-2e-06" ixz="-2e-06"/>
  </inertial>
  <visual>
    <origin xyz="-0.371098 0.51333 -0.184746" rpy="0 0 0"/>
    <geometry>
      <mesh filename="package://omnitrak/meshes/tapabase4_1.stl" scale="0.001 0.001 0.001"/>
    </geometry>
    <material name="silver"/>
  </visual>
  <collision>
    <origin xyz="-0.371098 0.51333 -0.184746" rpy="0 0 0"/>
    <geometry>
      <mesh filename="package://omnitrak/meshes/tapabase4_1.stl" scale="0.001 0.001 0.001"/>
    </geometry>
  </collision>
</link>

<link name="perfilfrontal1_1">
  <inertial>
    <origin xyz="-0.12544335933618028 -0.11928993292237543 0.297849128838488" rpy="0 0 0"/>
    <mass value="0.4948786348315057"/>
    <inertia ixx="0.003748" iyy="0.000209" izz="0.003627" ixy="0.0" iyz="-0.0" ixz="-0.0"/>
  </inertial>
  <visual>
    <origin xyz="0.172402 -0.03945 0.381502" rpy="0 0 0"/>
    <geometry>
      <mesh filename="package://omnitrak/meshes/perfilfrontal1_1.stl" scale="0.001 0.001 0.001"/>
    </geometry>
    <material name="silver"/>
  </visual>
  <collision>
    <origin xyz="0.172402 -0.03945 0.381502" rpy="0 0 0"/>
    <geometry>
      <mesh filename="package://omnitrak/meshes/perfilfrontal1_1.stl" scale="0.001 0.001 0.001"/>
    </geometry>
  </collision>
</link>

<link name="perfilfrontal2_1">
  <inertial>
    <origin xyz="0.12544335383015046 0.3940401433321573 -0.3045508711615107" rpy="0 0 0"/>
    <mass value="0.4948786348315057"/>
    <inertia ixx="0.003748" iyy="0.000209" izz="0.003627" ixy="0.0" iyz="0.0" ixz="-0.0"/>
  </inertial>
  <visual>
    <origin xyz="-0.179104 0.47388 -0.220898" rpy="0 0 0"/>
    <geometry>
      <mesh filename="package://omnitrak/meshes/perfilfrontal2_1.stl" scale="0.001 0.001 0.001"/>
    </geometry>
    <material name="silver"/>
  </visual>
  <collision>
    <origin xyz="-0.179104 0.47388 -0.220898" rpy="0 0 0"/>
    <geometry>
      <mesh filename="package://omnitrak/meshes/perfilfrontal2_1.stl" scale="0.001 0.001 0.001"/>
    </geometry>
  </collision>
</link>

<link name="plataforma_1">
  <inertial>
    <origin xyz="0.3810587303094576 -0.25837193292236427 0.3385217537945369" rpy="0 0 0"/>
    <mass value="0.5214939451995377"/>
    <inertia ixx="0.008757" iyy="0.01989" izz="0.028646" ixy="-0.0" iyz="-0.0" ixz="-0.0"/>
  </inertial>
  <visual>
    <origin xyz="0.377689 -0.178532 0.390283" rpy="0 0 0"/>
    <geometry>
      <mesh filename="package://omnitrak/meshes/plataforma_1.stl" scale="0.001 0.001 0.001"/>
    </geometry>
    <material name="silver"/>
  </visual>
  <collision>
    <origin xyz="0.377689 -0.178532 0.390283" rpy="0 0 0"/>
    <geometry>
      <mesh filename="package://omnitrak/meshes/plataforma_1.stl" scale="0.001 0.001 0.001"/>
    </geometry>
  </collision>
</link>

<link name="esquinerasuperior1_1">
  <inertial>
    <origin xyz="0.07073275011369964 -0.02836691313373195 0.00048799481896359687" rpy="0 0 0"/>
    <mass value="0.19277517775153036"/>
    <inertia ixx="0.000244" iyy="0.000244" izz="0.000486" ixy="7.2e-05" iyz="0.0" ixz="0.0"/>
  </inertial>
  <visual>
    <origin xyz="-0.18797 -0.079485 0.051653" rpy="0 0 0"/>
    <geometry>
      <mesh filename="package://omnitrak/meshes/esquinerasuperior1_1.stl" scale="0.001 0.001 0.001"/>
    </geometry>
    <material name="silver"/>
  </visual>
  <collision>
    <origin xyz="-0.18797 -0.079485 0.051653" rpy="0 0 0"/>
    <geometry>
      <mesh filename="package://omnitrak/meshes/esquinerasuperior1_1.stl" scale="0.001 0.001 0.001"/>
    </geometry>
  </collision>
</link>

<link name="esquinerasuperior2_1">
  <inertial>
    <origin xyz="-0.07073328949472862 0.02836704728900752 0.0004879948189608421" rpy="0 0 0"/>
    <mass value="0.19277517775153036"/>
    <inertia ixx="0.000244" iyy="0.000244" izz="0.000486" ixy="7.2e-05" iyz="-0.0" ixz="-0.0"/>
  </inertial>
  <visual>
    <origin xyz="0.18123 0.239165 0.051653" rpy="0 0 0"/>
    <geometry>
      <mesh filename="package://omnitrak/meshes/esquinerasuperior2_1.stl" scale="0.001 0.001 0.001"/>
    </geometry>
    <material name="silver"/>
  </visual>
  <collision>
    <origin xyz="0.18123 0.239165 0.051653" rpy="0 0 0"/>
    <geometry>
      <mesh filename="package://omnitrak/meshes/esquinerasuperior2_1.stl" scale="0.001 0.001 0.001"/>
    </geometry>
  </collision>
</link>

<link name="esquinerasuperior3_1">
  <inertial>
    <origin xyz="-0.07073328947914415 -0.02836691311814829 0.0004879948189621744" rpy="0 0 0"/>
    <mass value="0.19277517775153036"/>
    <inertia ixx="0.000244" iyy="0.000244" izz="0.000486" ixy="-7.2e-05" iyz="0.0" ixz="-0.0"/>
  </inertial>
  <visual>
    <origin xyz="0.18123 -0.079485 0.051653" rpy="0 0 0"/>
    <geometry>
      <mesh filename="package://omnitrak/meshes/esquinerasuperior3_1.stl" scale="0.001 0.001 0.001"/>
    </geometry>
    <material name="silver"/>
  </visual>
  <collision>
    <origin xyz="0.18123 -0.079485 0.051653" rpy="0 0 0"/>
    <geometry>
      <mesh filename="package://omnitrak/meshes/esquinerasuperior3_1.stl" scale="0.001 0.001 0.001"/>
    </geometry>
  </collision>
</link>

<link name="esquinerasuperior4_1">
  <inertial>
    <origin xyz="0.07073275009811555 0.02836704727342479 0.0004879948189622438" rpy="0 0 0"/>
    <mass value="0.19277517775153036"/>
    <inertia ixx="0.000244" iyy="0.000244" izz="0.000486" ixy="-7.2e-05" iyz="-0.0" ixz="0.0"/>
  </inertial>
  <visual>
    <origin xyz="-0.18797 0.239165 0.051653" rpy="0 0 0"/>
    <geometry>
      <mesh filename="package://omnitrak/meshes/esquinerasuperior4_1.stl" scale="0.001 0.001 0.001"/>
    </geometry>
    <material name="silver"/>
  </visual>
  <collision>
    <origin xyz="-0.18797 0.239165 0.051653" rpy="0 0 0"/>
    <geometry>
      <mesh filename="package://omnitrak/meshes/esquinerasuperior4_1.stl" scale="0.001 0.001 0.001"/>
    </geometry>
  </collision>
</link>

<link name="escotilla_1">
  <inertial>
    <origin xyz="-0.2510068387260623 6.707771836589327e-08 -0.0009444663335064704" rpy="0 0 0"/>
    <mass value="1.027085502634541"/>
    <inertia ixx="0.006951" iyy="0.014738" izz="0.021686" ixy="-0.0" iyz="-0.0" ixz="-0.0"/>
  </inertial>
  <visual>
    <origin xyz="-0.25457 0.07984 0.050653" rpy="0 0 0"/>
    <geometry>
      <mesh filename="package://omnitrak/meshes/escotilla_1.stl" scale="0.001 0.001 0.001"/>
    </geometry>
    <material name="silver"/>
  </visual>
  <collision>
    <origin xyz="-0.25457 0.07984 0.050653" rpy="0 0 0"/>
    <geometry>
      <mesh filename="package://omnitrak/meshes/escotilla_1.stl" scale="0.001 0.001 0.001"/>
    </geometry>
  </collision>
</link>

<link name="esquinera1_1">
  <inertial>
    <origin xyz="0.0268675852800368 0.026867731365198183 -0.00249993116151033" rpy="0 0 0"/>
    <mass value="0.049842566434574555"/>
    <inertia ixx="6.7e-05" iyy="6.7e-05" izz="0.000134" ixy="4.6e-05" iyz="0.0" ixz="0.0"/>
  </inertial>
  <visual>
    <origin xyz="0.294208 0.253024 0.113653" rpy="0 0 0"/>
    <geometry>
      <mesh filename="package://omnitrak/meshes/esquinera1_1.stl" scale="0.001 0.001 0.001"/>
    </geometry>
    <material name="silver"/>
  </visual>
  <collision>
    <origin xyz="0.294208 0.253024 0.113653" rpy="0 0 0"/>
    <geometry>
      <mesh filename="package://omnitrak/meshes/esquinera1_1.stl" scale="0.001 0.001 0.001"/>
    </geometry>
  </collision>
</link>

<link name="esquinera2_1">
  <inertial>
    <origin xyz="0.0268675852800368 -0.026867520955412977 -0.002499931161511232" rpy="0 0 0"/>
    <mass value="0.049842566434574555"/>
    <inertia ixx="6.7e-05" iyy="6.7e-05" izz="0.000134" ixy="-4.6e-05" iyz="-0.0" ixz="-0.0"/>
  </inertial>
  <visual>
    <origin xyz="0.294208 -0.093344 0.113653" rpy="0 0 0"/>
    <geometry>
      <mesh filename="package://omnitrak/meshes/esquinera2_1.stl" scale="0.001 0.001 0.001"/>
    </geometry>
    <material name="silver"/>
  </visual>
  <collision>
    <origin xyz="0.294208 -0.093344 0.113653" rpy="0 0 0"/>
    <geometry>
      <mesh filename="package://omnitrak/meshes/esquinera2_1.stl" scale="0.001 0.001 0.001"/>
    </geometry>
  </collision>
</link>

<link name="esquinera3_1">
  <inertial>
    <origin xyz="-0.02686759078605777 -0.026867520955429117 -0.0024999311615111486" rpy="0 0 0"/>
    <mass value="0.049842566434574555"/>
    <inertia ixx="6.7e-05" iyy="6.7e-05" izz="0.000134" ixy="4.6e-05" iyz="-0.0" ixz="0.0"/>
  </inertial>
  <visual>
    <origin xyz="-0.30091 -0.093344 0.113653" rpy="0 0 0"/>
    <geometry>
      <mesh filename="package://omnitrak/meshes/esquinera3_1.stl" scale="0.001 0.001 0.001"/>
    </geometry>
    <material name="silver"/>
  </visual>
  <collision>
    <origin xyz="-0.30091 -0.093344 0.113653" rpy="0 0 0"/>
    <geometry>
      <mesh filename="package://omnitrak/meshes/esquinera3_1.stl" scale="0.001 0.001 0.001"/>
    </geometry>
  </collision>
</link>

<link name="esquinera4_1">
  <inertial>
    <origin xyz="-0.02686759078605694 0.02686773136521503 -0.002499931161510288" rpy="0 0 0"/>
    <mass value="0.049842566434574555"/>
    <inertia ixx="6.7e-05" iyy="6.7e-05" izz="0.000134" ixy="-4.6e-05" iyz="0.0" ixz="0.0"/>
  </inertial>
  <visual>
    <origin xyz="-0.30091 0.253024 0.113653" rpy="0 0 0"/>
    <geometry>
      <mesh filename="package://omnitrak/meshes/esquinera4_1.stl" scale="0.001 0.001 0.001"/>
    </geometry>
    <material name="silver"/>
  </visual>
  <collision>
    <origin xyz="-0.30091 0.253024 0.113653" rpy="0 0 0"/>
    <geometry>
      <mesh filename="package://omnitrak/meshes/esquinera4_1.stl" scale="0.001 0.001 0.001"/>
    </geometry>
  </collision>
</link>

<link name="baseps1_1">
  <inertial>
    <origin xyz="0.042452497908371994 0.23971488860821644 0.11323883860242376" rpy="0 0 0"/>
    <mass value="0.17526105199028302"/>
    <inertia ixx="0.000101" iyy="0.000172" izz="0.0001" ixy="0.0" iyz="-2.1e-05" ixz="-0.0"/>
  </inertial>
  <visual>
    <origin xyz="-0.185752 0.131366 0.210491" rpy="0 0 0"/>
    <geometry>
      <mesh filename="package://omnitrak/meshes/baseps1_1.stl" scale="0.001 0.001 0.001"/>
    </geometry>
    <material name="silver"/>
  </visual>
  <collision>
    <origin xyz="-0.185752 0.131366 0.210491" rpy="0 0 0"/>
    <geometry>
      <mesh filename="package://omnitrak/meshes/baseps1_1.stl" scale="0.001 0.001 0.001"/>
    </geometry>
  </collision>
</link>

<link name="baseps2_1">
  <inertial>
    <origin xyz="0.29770249658559134 0.1301628886082138 0.11323883860242356" rpy="0 0 0"/>
    <mass value="0.17526105199028302"/>
    <inertia ixx="0.000101" iyy="0.000172" izz="0.0001" ixy="0.0" iyz="-2.1e-05" ixz="-0.0"/>
  </inertial>
  <visual>
    <origin xyz="0.519205 0.021814 0.210491" rpy="0 0 0"/>
    <geometry>
      <mesh filename="package://omnitrak/meshes/baseps2_1.stl" scale="0.001 0.001 0.001"/>
    </geometry>
    <material name="silver"/>
  </visual>
  <collision>
    <origin xyz="0.519205 0.021814 0.210491" rpy="0 0 0"/>
    <geometry>
      <mesh filename="package://omnitrak/meshes/baseps2_1.stl" scale="0.001 0.001 0.001"/>
    </geometry>
  </collision>
</link>

<link name="baseps3_1">
  <inertial>
    <origin xyz="0.042452497908371634 -0.2395146781984298 0.2779188386024242" rpy="0 0 0"/>
    <mass value="0.17526105199028302"/>
    <inertia ixx="0.000101" iyy="0.000172" izz="0.0001" ixy="0.0" iyz="2.1e-05" ixz="0.0"/>
  </inertial>
  <visual>
    <origin xyz="-0.185752 0.028314 0.375171" rpy="0 0 0"/>
    <geometry>
      <mesh filename="package://omnitrak/meshes/baseps3_1.stl" scale="0.001 0.001 0.001"/>
    </geometry>
    <material name="silver"/>
  </visual>
  <collision>
    <origin xyz="-0.185752 0.028314 0.375171" rpy="0 0 0"/>
    <geometry>
      <mesh filename="package://omnitrak/meshes/baseps3_1.stl" scale="0.001 0.001 0.001"/>
    </geometry>
  </collision>
</link>

<link name="baseps4_1">
  <inertial>
    <origin xyz="0.2977024965855922 -0.12996367819842855 0.2779188386024242" rpy="0 0 0"/>
    <mass value="0.17526105199028302"/>
    <inertia ixx="0.000101" iyy="0.000172" izz="0.0001" ixy="0.0" iyz="2.1e-05" ixz="0.0"/>
  </inertial>
  <visual>
    <origin xyz="0.519205 0.137865 0.375171" rpy="0 0 0"/>
    <geometry>
      <mesh filename="package://omnitrak/meshes/baseps4_1.stl" scale="0.001 0.001 0.001"/>
    </geometry>
    <material name="silver"/>
  </visual>
  <collision>
    <origin xyz="0.519205 0.137865 0.375171" rpy="0 0 0"/>
    <geometry>
      <mesh filename="package://omnitrak/meshes/baseps4_1.stl" scale="0.001 0.001 0.001"/>
    </geometry>
  </collision>
</link>

<link name="mediahoja1_1">
  <inertial>
    <origin xyz="8.556070684295758e-05 -0.01681666324049086 -0.032383614512758396" rpy="0 0 0"/>
    <mass value="0.29514006821253114"/>
    <inertia ixx="0.000211" iyy="0.000255" izz="0.000256" ixy="-0.0" iyz="-6.5e-05" ixz="0.0"/>
  </inertial>
  <visual>
    <origin xyz="0.221503 0.274593 0.063553" rpy="0 0 0"/>
    <geometry>
      <mesh filename="package://omnitrak/meshes/mediahoja1_1.stl" scale="0.001 0.001 0.001"/>
    </geometry>
    <material name="silver"/>
  </visual>
  <collision>
    <origin xyz="0.221503 0.274593 0.063553" rpy="0 0 0"/>
    <geometry>
      <mesh filename="package://omnitrak/meshes/mediahoja1_1.stl" scale="0.001 0.001 0.001"/>
    </geometry>
  </collision>
</link>

<link name="mediahoja2_1">
  <inertial>
    <origin xyz="-8.456621287911137e-05 -0.016816663240492413 -0.03238361451275844" rpy="0 0 0"/>
    <mass value="0.29514006821253114"/>
    <inertia ixx="0.000211" iyy="0.000255" izz="0.000256" ixy="0.0" iyz="-6.5e-05" ixz="-0.0"/>
  </inertial>
  <visual>
    <origin xyz="-0.228204 0.274593 0.063553" rpy="0 0 0"/>
    <geometry>
      <mesh filename="package://omnitrak/meshes/mediahoja2_1.stl" scale="0.001 0.001 0.001"/>
    </geometry>
    <material name="silver"/>
  </visual>
  <collision>
    <origin xyz="-0.228204 0.274593 0.063553" rpy="0 0 0"/>
    <geometry>
      <mesh filename="package://omnitrak/meshes/mediahoja2_1.stl" scale="0.001 0.001 0.001"/>
    </geometry>
  </collision>
</link>

<link name="mediahoja3_1">
  <inertial>
    <origin xyz="8.556070684140327e-05 0.01681587365027601 -0.032383614512758924" rpy="0 0 0"/>
    <mass value="0.29514006821253114"/>
    <inertia ixx="0.000211" iyy="0.000255" izz="0.000256" ixy="0.0" iyz="6.5e-05" ixz="0.0"/>
  </inertial>
  <visual>
    <origin xyz="0.221503 -0.115114 0.063553" rpy="0 0 0"/>
    <geometry>
      <mesh filename="package://omnitrak/meshes/mediahoja3_1.stl" scale="0.001 0.001 0.001"/>
    </geometry>
    <material name="silver"/>
  </visual>
  <collision>
    <origin xyz="0.221503 -0.115114 0.063553" rpy="0 0 0"/>
    <geometry>
      <mesh filename="package://omnitrak/meshes/mediahoja3_1.stl" scale="0.001 0.001 0.001"/>
    </geometry>
  </collision>
</link>

<link name="mediahoja4_1">
  <inertial>
    <origin xyz="-8.456621287833421e-05 0.016815873650278673 -0.032383614512758965" rpy="0 0 0"/>
    <mass value="0.29514006821253114"/>
    <inertia ixx="0.000211" iyy="0.000255" izz="0.000256" ixy="-0.0" iyz="6.5e-05" ixz="-0.0"/>
  </inertial>
  <visual>
    <origin xyz="-0.228204 -0.115114 0.063553" rpy="0 0 0"/>
    <geometry>
      <mesh filename="package://omnitrak/meshes/mediahoja4_1.stl" scale="0.001 0.001 0.001"/>
    </geometry>
    <material name="silver"/>
  </visual>
  <collision>
    <origin xyz="-0.228204 -0.115114 0.063553" rpy="0 0 0"/>
    <geometry>
      <mesh filename="package://omnitrak/meshes/mediahoja4_1.stl" scale="0.001 0.001 0.001"/>
    </geometry>
  </collision>
</link>

<link name="soportemotorsito1_1">
  <inertial>
    <origin xyz="2.743102123226038e-07 1.3828330891474394e-07 0.014999568838489671" rpy="0 0 0"/>
    <mass value="0.003053628059289323"/>
    <inertia ixx="0.0" iyy="0.0" izz="0.0" ixy="0.0" iyz="-0.0" ixz="0.0"/>
  </inertial>
  <visual>
    <origin xyz="0.190861 0.330305 0.10889" rpy="0 0 0"/>
    <geometry>
      <mesh filename="package://omnitrak/meshes/soportemotorsito1_1.stl" scale="0.001 0.001 0.001"/>
    </geometry>
    <material name="silver"/>
  </visual>
  <collision>
    <origin xyz="0.190861 0.330305 0.10889" rpy="0 0 0"/>
    <geometry>
      <mesh filename="package://omnitrak/meshes/soportemotorsito1_1.stl" scale="0.001 0.001 0.001"/>
    </geometry>
  </collision>
</link>

<link name="soportemotorsito2_1">
  <inertial>
    <origin xyz="-2.798165286144183e-07 1.382833087482105e-07 0.01499956883848974" rpy="0 0 0"/>
    <mass value="0.003053628059289323"/>
    <inertia ixx="0.0" iyy="0.0" izz="0.0" ixy="-0.0" iyz="0.0" ixz="0.0"/>
  </inertial>
  <visual>
    <origin xyz="-0.197563 0.330305 0.10889" rpy="0 0 0"/>
    <geometry>
      <mesh filename="package://omnitrak/meshes/soportemotorsito2_1.stl" scale="0.001 0.001 0.001"/>
    </geometry>
    <material name="silver"/>
  </visual>
  <collision>
    <origin xyz="-0.197563 0.330305 0.10889" rpy="0 0 0"/>
    <geometry>
      <mesh filename="package://omnitrak/meshes/soportemotorsito2_1.stl" scale="0.001 0.001 0.001"/>
    </geometry>
  </collision>
</link>

<link name="soportemotorsito3_1">
  <inertial>
    <origin xyz="2.743102109070694e-07 7.212647698540131e-08 0.014999568838491184" rpy="0 0 0"/>
    <mass value="0.003053628059289323"/>
    <inertia ixx="0.0" iyy="0.0" izz="0.0" ixy="-0.0" iyz="0.0" ixz="0.0"/>
  </inertial>
  <visual>
    <origin xyz="0.190861 -0.170825 0.10889" rpy="0 0 0"/>
    <geometry>
      <mesh filename="package://omnitrak/meshes/soportemotorsito3_1.stl" scale="0.001 0.001 0.001"/>
    </geometry>
    <material name="silver"/>
  </visual>
  <collision>
    <origin xyz="0.190861 -0.170825 0.10889" rpy="0 0 0"/>
    <geometry>
      <mesh filename="package://omnitrak/meshes/soportemotorsito3_1.stl" scale="0.001 0.001 0.001"/>
    </geometry>
  </collision>
</link>

<link name="soportemotorsito4_1">
  <inertial>
    <origin xyz="-2.7981652603314977e-07 7.212647912258063e-08 0.0149995688384892" rpy="0 0 0"/>
    <mass value="0.003053628059289323"/>
    <inertia ixx="0.0" iyy="0.0" izz="0.0" ixy="0.0" iyz="0.0" ixz="0.0"/>
  </inertial>
  <visual>
    <origin xyz="-0.197563 -0.170825 0.10889" rpy="0 0 0"/>
    <geometry>
      <mesh filename="package://omnitrak/meshes/soportemotorsito4_1.stl" scale="0.001 0.001 0.001"/>
    </geometry>
    <material name="silver"/>
  </visual>
  <collision>
    <origin xyz="-0.197563 -0.170825 0.10889" rpy="0 0 0"/>
    <geometry>
      <mesh filename="package://omnitrak/meshes/soportemotorsito4_1.stl" scale="0.001 0.001 0.001"/>
    </geometry>
  </collision>
</link>

<link name="apoyomotor1_1">
  <inertial>
    <origin xyz="-0.030655056404964742 -0.022182654727162965 0.0015870688384911624" rpy="0 0 0"/>
    <mass value="0.030305585092970117"/>
    <inertia ixx="8e-06" iyy="1.6e-05" izz="2.4e-05" ixy="0.0" iyz="-0.0" ixz="0.0"/>
  </inertial>
  <visual>
    <origin xyz="0.190861 -0.170825 0.07889" rpy="0 0 0"/>
    <geometry>
      <mesh filename="package://omnitrak/meshes/apoyomotor1_1.stl" scale="0.001 0.001 0.001"/>
    </geometry>
    <material name="silver"/>
  </visual>
  <collision>
    <origin xyz="0.190861 -0.170825 0.07889" rpy="0 0 0"/>
    <geometry>
      <mesh filename="package://omnitrak/meshes/apoyomotor1_1.stl" scale="0.001 0.001 0.001"/>
    </geometry>
  </collision>
</link>

<link name="apoyomotor2_1">
  <inertial>
    <origin xyz="-0.030655056404963715 0.02218286513694806 0.0015870688384895665" rpy="0 0 0"/>
    <mass value="0.030305585092970117"/>
    <inertia ixx="8e-06" iyy="1.6e-05" izz="2.4e-05" ixy="-0.0" iyz="0.0" ixz="0.0"/>
  </inertial>
  <visual>
    <origin xyz="0.190861 0.330305 0.07889" rpy="0 0 0"/>
    <geometry>
      <mesh filename="package://omnitrak/meshes/apoyomotor2_1.stl" scale="0.001 0.001 0.001"/>
    </geometry>
    <material name="silver"/>
  </visual>
  <collision>
    <origin xyz="0.190861 0.330305 0.07889" rpy="0 0 0"/>
    <geometry>
      <mesh filename="package://omnitrak/meshes/apoyomotor2_1.stl" scale="0.001 0.001 0.001"/>
    </geometry>
  </collision>
</link>

<link name="apoyomotor3_1">
  <inertial>
    <origin xyz="0.03065505089892706 0.02218286513694695 0.0015870688384895804" rpy="0 0 0"/>
    <mass value="0.030305585092970117"/>
    <inertia ixx="8e-06" iyy="1.6e-05" izz="2.4e-05" ixy="0.0" iyz="0.0" ixz="0.0"/>
  </inertial>
  <visual>
    <origin xyz="-0.197563 0.330305 0.07889" rpy="0 0 0"/>
    <geometry>
      <mesh filename="package://omnitrak/meshes/apoyomotor3_1.stl" scale="0.001 0.001 0.001"/>
    </geometry>
    <material name="silver"/>
  </visual>
  <collision>
    <origin xyz="-0.197563 0.330305 0.07889" rpy="0 0 0"/>
    <geometry>
      <mesh filename="package://omnitrak/meshes/apoyomotor3_1.stl" scale="0.001 0.001 0.001"/>
    </geometry>
  </collision>
</link>

<link name="apoyomotor4_1">
  <inertial>
    <origin xyz="0.03065505089892842 -0.022182654727160356 0.001587068838489053" rpy="0 0 0"/>
    <mass value="0.030305585092970117"/>
    <inertia ixx="8e-06" iyy="1.6e-05" izz="2.4e-05" ixy="-0.0" iyz="0.0" ixz="0.0"/>
  </inertial>
  <visual>
    <origin xyz="-0.197563 -0.170825 0.07889" rpy="0 0 0"/>
    <geometry>
      <mesh filename="package://omnitrak/meshes/apoyomotor4_1.stl" scale="0.001 0.001 0.001"/>
    </geometry>
    <material name="silver"/>
  </visual>
  <collision>
    <origin xyz="-0.197563 -0.170825 0.07889" rpy="0 0 0"/>
    <geometry>
      <mesh filename="package://omnitrak/meshes/apoyomotor4_1.stl" scale="0.001 0.001 0.001"/>
    </geometry>
  </collision>
</link>

<link name="motor1_1">
  <inertial>
    <origin xyz="0.031871923185060935 -1.666551046036746e-05 0.018651719317415417" rpy="0 0 0"/>
    <mass value="0.10837582990116511"/>
    <inertia ixx="1.9e-05" iyy="0.000125" izz="0.000128" ixy="-0.0" iyz="0.0" ixz="-7e-06"/>
  </inertial>
  <visual>
    <origin xyz="0.221503 -0.145114 0.075715" rpy="0 0 0"/>
    <geometry>
      <mesh filename="package://omnitrak/meshes/motor1_1.stl" scale="0.001 0.001 0.001"/>
    </geometry>
    <material name="silver"/>
  </visual>
  <collision>
    <origin xyz="0.221503 -0.145114 0.075715" rpy="0 0 0"/>
    <geometry>
      <mesh filename="package://omnitrak/meshes/motor1_1.stl" scale="0.001 0.001 0.001"/>
    </geometry>
  </collision>
</link>

<link name="motor2_1">
  <inertial>
    <origin xyz="0.03187192318506191 -1.6590578704844816e-05 0.01865171931741383" rpy="0 0 0"/>
    <mass value="0.10837582990116511"/>
    <inertia ixx="1.9e-05" iyy="0.000125" izz="0.000128" ixy="-0.0" iyz="0.0" ixz="-7e-06"/>
  </inertial>
  <visual>
    <origin xyz="0.221503 0.304593 0.075715" rpy="0 0 0"/>
    <geometry>
      <mesh filename="package://omnitrak/meshes/motor2_1.stl" scale="0.001 0.001 0.001"/>
    </geometry>
    <material name="silver"/>
  </visual>
  <collision>
    <origin xyz="0.221503 0.304593 0.075715" rpy="0 0 0"/>
    <geometry>
      <mesh filename="package://omnitrak/meshes/motor2_1.stl" scale="0.001 0.001 0.001"/>
    </geometry>
  </collision>
</link>

<link name="motor3_1">
  <inertial>
    <origin xyz="-0.031870928691098255 1.587592024648865e-05 0.018651719317413787" rpy="0 0 0"/>
    <mass value="0.10837582990116511"/>
    <inertia ixx="1.9e-05" iyy="0.000125" izz="0.000128" ixy="-0.0" iyz="-0.0" ixz="7e-06"/>
  </inertial>
  <visual>
    <origin xyz="-0.228204 0.304593 0.075715" rpy="0 0 0"/>
    <geometry>
      <mesh filename="package://omnitrak/meshes/motor3_1.stl" scale="0.001 0.001 0.001"/>
    </geometry>
    <material name="silver"/>
  </visual>
  <collision>
    <origin xyz="-0.228204 0.304593 0.075715" rpy="0 0 0"/>
    <geometry>
      <mesh filename="package://omnitrak/meshes/motor3_1.stl" scale="0.001 0.001 0.001"/>
    </geometry>
  </collision>
</link>

<link name="motor4_1">
  <inertial>
    <origin xyz="-0.03187092869109712 1.5800988492742363e-05 0.018651719317413447" rpy="0 0 0"/>
    <mass value="0.10837582990116511"/>
    <inertia ixx="1.9e-05" iyy="0.000125" izz="0.000128" ixy="-0.0" iyz="-0.0" ixz="7e-06"/>
  </inertial>
  <visual>
    <origin xyz="-0.228204 -0.145114 0.075715" rpy="0 0 0"/>
    <geometry>
      <mesh filename="package://omnitrak/meshes/motor4_1.stl" scale="0.001 0.001 0.001"/>
    </geometry>
    <material name="silver"/>
  </visual>
  <collision>
    <origin xyz="-0.228204 -0.145114 0.075715" rpy="0 0 0"/>
    <geometry>
      <mesh filename="package://omnitrak/meshes/motor4_1.stl" scale="0.001 0.001 0.001"/>
    </geometry>
  </collision>
</link>

<link name="acoplerigido1_1">
  <inertial>
    <origin xyz="0.0002587849006582821 -0.0005522684512831166 -0.012500434733916599" rpy="0 0 0"/>
    <mass value="0.016005907323342845"/>
    <inertia ixx="1e-06" iyy="1e-06" izz="1e-06" ixy="-0.0" iyz="0.0" ixz="0.0"/>
  </inertial>
  <visual>
    <origin xyz="0.221503 -0.145114 0.075715" rpy="0 0 0"/>
    <geometry>
      <mesh filename="package://omnitrak/meshes/acoplerigido1_1.stl" scale="0.001 0.001 0.001"/>
    </geometry>
    <material name="silver"/>
  </visual>
  <collision>
    <origin xyz="0.221503 -0.145114 0.075715" rpy="0 0 0"/>
    <geometry>
      <mesh filename="package://omnitrak/meshes/acoplerigido1_1.stl" scale="0.001 0.001 0.001"/>
    </geometry>
  </collision>
</link>

<link name="acoplerigido2_1">
  <inertial>
    <origin xyz="0.00025878490065942006 -0.0005521935195272887 -0.012500434733918125" rpy="0 0 0"/>
    <mass value="0.016005907323342845"/>
    <inertia ixx="1e-06" iyy="1e-06" izz="1e-06" ixy="-0.0" iyz="0.0" ixz="0.0"/>
  </inertial>
  <visual>
    <origin xyz="0.221503 0.304593 0.075715" rpy="0 0 0"/>
    <geometry>
      <mesh filename="package://omnitrak/meshes/acoplerigido2_1.stl" scale="0.001 0.001 0.001"/>
    </geometry>
    <material name="silver"/>
  </visual>
  <collision>
    <origin xyz="0.221503 0.304593 0.075715" rpy="0 0 0"/>
    <geometry>
      <mesh filename="package://omnitrak/meshes/acoplerigido2_1.stl" scale="0.001 0.001 0.001"/>
    </geometry>
  </collision>
</link>

<link name="acoplerigido3_1">
  <inertial>
    <origin xyz="0.00025878622343764035 -0.0005521935195281213 -0.012500434733918167" rpy="0 0 0"/>
    <mass value="0.016005907323342845"/>
    <inertia ixx="1e-06" iyy="1e-06" izz="1e-06" ixy="-0.0" iyz="0.0" ixz="0.0"/>
  </inertial>
  <visual>
    <origin xyz="-0.228204 0.304593 0.075715" rpy="0 0 0"/>
    <geometry>
      <mesh filename="package://omnitrak/meshes/acoplerigido3_1.stl" scale="0.001 0.001 0.001"/>
    </geometry>
    <material name="silver"/>
  </visual>
  <collision>
    <origin xyz="-0.228204 0.304593 0.075715" rpy="0 0 0"/>
    <geometry>
      <mesh filename="package://omnitrak/meshes/acoplerigido3_1.stl" scale="0.001 0.001 0.001"/>
    </geometry>
  </collision>
</link>

<link name="acoplerigido4_1">
  <inertial>
    <origin xyz="0.0002587862234391114 -0.0005522684512803411 -0.012500434733918514" rpy="0 0 0"/>
    <mass value="0.016005907323342845"/>
    <inertia ixx="1e-06" iyy="1e-06" izz="1e-06" ixy="-0.0" iyz="0.0" ixz="0.0"/>
  </inertial>
  <visual>
    <origin xyz="-0.228204 -0.145114 0.075715" rpy="0 0 0"/>
    <geometry>
      <mesh filename="package://omnitrak/meshes/acoplerigido4_1.stl" scale="0.001 0.001 0.001"/>
    </geometry>
    <material name="silver"/>
  </visual>
  <collision>
    <origin xyz="-0.228204 -0.145114 0.075715" rpy="0 0 0"/>
    <geometry>
      <mesh filename="package://omnitrak/meshes/acoplerigido4_1.stl" scale="0.001 0.001 0.001"/>
    </geometry>
  </collision>
</link>

<link name="acopledeleje1_1">
  <inertial>
    <origin xyz="-0.22820450209176021 -0.14511343226099166 0.07676140730469501" rpy="0 0 0"/>
    <mass value="0.02836553626300299"/>
    <inertia ixx="9e-06" iyy="9e-06" izz="0.0" ixy="-0.0" iyz="-0.0" ixz="0.0"/>
  </inertial>
  <visual>
    <origin xyz="-0.456409 -0.290227 0.201431" rpy="0 0 0"/>
    <geometry>
      <mesh filename="package://omnitrak/meshes/acopledeleje1_1.stl" scale="0.001 0.001 0.001"/>
    </geometry>
    <material name="silver"/>
  </visual>
  <collision>
    <origin xyz="-0.456409 -0.290227 0.201431" rpy="0 0 0"/>
    <geometry>
      <mesh filename="package://omnitrak/meshes/acopledeleje1_1.stl" scale="0.001 0.001 0.001"/>
    </geometry>
  </collision>
</link>

<link name="acopledeleje2_1">
  <inertial>
    <origin xyz="0.2215024965854591 -0.14511343226099443 0.07676140730469701" rpy="0 0 0"/>
    <mass value="0.02836553626300299"/>
    <inertia ixx="9e-06" iyy="9e-06" izz="0.0" ixy="-0.0" iyz="-0.0" ixz="0.0"/>
  </inertial>
  <visual>
    <origin xyz="0.443005 -0.290227 0.201431" rpy="0 0 0"/>
    <geometry>
      <mesh filename="package://omnitrak/meshes/acopledeleje2_1.stl" scale="0.001 0.001 0.001"/>
    </geometry>
    <material name="silver"/>
  </visual>
  <collision>
    <origin xyz="0.443005 -0.290227 0.201431" rpy="0 0 0"/>
    <geometry>
      <mesh filename="package://omnitrak/meshes/acopledeleje2_1.stl" scale="0.001 0.001 0.001"/>
    </geometry>
  </collision>
</link>

<link name="acopledeleje3_1">
  <inertial>
    <origin xyz="0.22150249658572502 0.30459364267077943 0.07676140730469543" rpy="0 0 0"/>
    <mass value="0.02836553626300299"/>
    <inertia ixx="9e-06" iyy="9e-06" izz="0.0" ixy="-0.0" iyz="0.0" ixz="-0.0"/>
  </inertial>
  <visual>
    <origin xyz="0.443005 0.609187 0.201431" rpy="0 0 0"/>
    <geometry>
      <mesh filename="package://omnitrak/meshes/acopledeleje3_1.stl" scale="0.001 0.001 0.001"/>
    </geometry>
    <material name="silver"/>
  </visual>
  <collision>
    <origin xyz="0.443005 0.609187 0.201431" rpy="0 0 0"/>
    <geometry>
      <mesh filename="package://omnitrak/meshes/acopledeleje3_1.stl" scale="0.001 0.001 0.001"/>
    </geometry>
  </collision>
</link>

<link name="acopledeleje4_1">
  <inertial>
    <origin xyz="-0.22820450209149648 0.30459364267077854 0.07676140730469536" rpy="0 0 0"/>
    <mass value="0.02836553626300299"/>
    <inertia ixx="9e-06" iyy="9e-06" izz="0.0" ixy="-0.0" iyz="0.0" ixz="-0.0"/>
  </inertial>
  <visual>
    <origin xyz="-0.456409 0.609187 0.201431" rpy="0 0 0"/>
    <geometry>
      <mesh filename="package://omnitrak/meshes/acopledeleje4_1.stl" scale="0.001 0.001 0.001"/>
    </geometry>
    <material name="silver"/>
  </visual>
  <collision>
    <origin xyz="-0.456409 0.609187 0.201431" rpy="0 0 0"/>
    <geometry>
      <mesh filename="package://omnitrak/meshes/acopledeleje4_1.stl" scale="0.001 0.001 0.001"/>
    </geometry>
  </collision>
</link>

<link name="flange1_1">
  <inertial>
    <origin xyz="4.97908435453942e-07 -4.3226104542992694e-07 0.001587068838489164" rpy="0 0 0"/>
    <mass value="0.014682547425817113"/>
    <inertia ixx="1e-06" iyy="1e-06" izz="2e-06" ixy="-0.0" iyz="0.0" ixz="0.0"/>
  </inertial>
  <visual>
    <origin xyz="-0.228204 -0.145114 0.15124" rpy="0 0 0"/>
    <geometry>
      <mesh filename="package://omnitrak/meshes/flange1_1.stl" scale="0.001 0.001 0.001"/>
    </geometry>
    <material name="silver"/>
  </visual>
  <collision>
    <origin xyz="-0.228204 -0.145114 0.15124" rpy="0 0 0"/>
    <geometry>
      <mesh filename="package://omnitrak/meshes/flange1_1.stl" scale="0.001 0.001 0.001"/>
    </geometry>
  </collision>
</link>

<link name="flange2_1">
  <inertial>
    <origin xyz="4.965856547078928e-07 -4.32260921945371e-07 0.001587068838491107" rpy="0 0 0"/>
    <mass value="0.014682547425817113"/>
    <inertia ixx="1e-06" iyy="1e-06" izz="2e-06" ixy="0.0" iyz="0.0" ixz="0.0"/>
  </inertial>
  <visual>
    <origin xyz="0.221503 -0.145114 0.15124" rpy="0 0 0"/>
    <geometry>
      <mesh filename="package://omnitrak/meshes/flange2_1.stl" scale="0.001 0.001 0.001"/>
    </geometry>
    <material name="silver"/>
  </visual>
  <collision>
    <origin xyz="0.221503 -0.145114 0.15124" rpy="0 0 0"/>
    <geometry>
      <mesh filename="package://omnitrak/meshes/flange2_1.stl" scale="0.001 0.001 0.001"/>
    </geometry>
  </collision>
</link>

<link name="flange3_1">
  <inertial>
    <origin xyz="4.979084340939188e-07 -3.573292937653072e-07 0.001587068838489497" rpy="0 0 0"/>
    <mass value="0.014682547425817113"/>
    <inertia ixx="1e-06" iyy="1e-06" izz="2e-06" ixy="-0.0" iyz="0.0" ixz="0.0"/>
  </inertial>
  <visual>
    <origin xyz="-0.228204 0.304593 0.15124" rpy="0 0 0"/>
    <geometry>
      <mesh filename="package://omnitrak/meshes/flange3_1.stl" scale="0.001 0.001 0.001"/>
    </geometry>
    <material name="silver"/>
  </visual>
  <collision>
    <origin xyz="-0.228204 0.304593 0.15124" rpy="0 0 0"/>
    <geometry>
      <mesh filename="package://omnitrak/meshes/flange3_1.stl" scale="0.001 0.001 0.001"/>
    </geometry>
  </collision>
</link>

<link name="flange4_1">
  <inertial>
    <origin xyz="4.965856552630044e-07 -3.573292929881511e-07 0.0015870688384896914" rpy="0 0 0"/>
    <mass value="0.014682547425817113"/>
    <inertia ixx="1e-06" iyy="1e-06" izz="2e-06" ixy="-0.0" iyz="0.0" ixz="-0.0"/>
  </inertial>
  <visual>
    <origin xyz="0.221503 0.304593 0.15124" rpy="0 0 0"/>
    <geometry>
      <mesh filename="package://omnitrak/meshes/flange4_1.stl" scale="0.001 0.001 0.001"/>
    </geometry>
    <material name="silver"/>
  </visual>
  <collision>
    <origin xyz="0.221503 0.304593 0.15124" rpy="0 0 0"/>
    <geometry>
      <mesh filename="package://omnitrak/meshes/flange4_1.stl" scale="0.001 0.001 0.001"/>
    </geometry>
  </collision>
</link>

<link name="pinza1_1">
  <inertial>
    <origin xyz="0.007071496585591308 0.03993441304018047 -0.036821208179778575" rpy="0 0 0"/>
    <mass value="0.2592926194093395"/>
    <inertia ixx="0.000552" iyy="0.000435" izz="0.000175" ixy="0.0" iyz="0.000141" ixz="-0.0"/>
  </inertial>
  <visual>
    <origin xyz="0.228574 -0.138042 0.15124" rpy="0 0 0"/>
    <geometry>
      <mesh filename="package://omnitrak/meshes/pinza1_1.stl" scale="0.001 0.001 0.001"/>
    </geometry>
    <material name="silver"/>
  </visual>
  <collision>
    <origin xyz="0.228574 -0.138042 0.15124" rpy="0 0 0"/>
    <geometry>
      <mesh filename="package://omnitrak/meshes/pinza1_1.stl" scale="0.001 0.001 0.001"/>
    </geometry>
  </collision>
</link>

<link name="pinza2_1">
  <inertial>
    <origin xyz="0.007071497908372526 0.03993441304018297 -0.036821208179780573" rpy="0 0 0"/>
    <mass value="0.2592926194093395"/>
    <inertia ixx="0.000552" iyy="0.000435" izz="0.000175" ixy="0.0" iyz="0.000141" ixz="0.0"/>
  </inertial>
  <visual>
    <origin xyz="-0.221133 -0.138042 0.15124" rpy="0 0 0"/>
    <geometry>
      <mesh filename="package://omnitrak/meshes/pinza2_1.stl" scale="0.001 0.001 0.001"/>
    </geometry>
    <material name="silver"/>
  </visual>
  <collision>
    <origin xyz="-0.221133 -0.138042 0.15124" rpy="0 0 0"/>
    <geometry>
      <mesh filename="package://omnitrak/meshes/pinza2_1.stl" scale="0.001 0.001 0.001"/>
    </geometry>
  </collision>
</link>

<link name="pinza3_1">
  <inertial>
    <origin xyz="0.007071497908369723 -0.03993420263039604 -0.036821208179780324" rpy="0 0 0"/>
    <mass value="0.2592926194093395"/>
    <inertia ixx="0.000552" iyy="0.000435" izz="0.000175" ixy="-0.0" iyz="-0.000141" ixz="-0.0"/>
  </inertial>
  <visual>
    <origin xyz="-0.221133 0.297522 0.15124" rpy="0 0 0"/>
    <geometry>
      <mesh filename="package://omnitrak/meshes/pinza3_1.stl" scale="0.001 0.001 0.001"/>
    </geometry>
    <material name="silver"/>
  </visual>
  <collision>
    <origin xyz="-0.221133 0.297522 0.15124" rpy="0 0 0"/>
    <geometry>
      <mesh filename="package://omnitrak/meshes/pinza3_1.stl" scale="0.001 0.001 0.001"/>
    </geometry>
  </collision>
</link>

<link name="pinza4_1">
  <inertial>
    <origin xyz="0.007071496585592113 -0.03993420263039571 -0.036821208179779824" rpy="0 0 0"/>
    <mass value="0.2592926194093395"/>
    <inertia ixx="0.000552" iyy="0.000435" izz="0.000175" ixy="0.0" iyz="-0.000141" ixz="0.0"/>
  </inertial>
  <visual>
    <origin xyz="0.228574 0.297522 0.15124" rpy="0 0 0"/>
    <geometry>
      <mesh filename="package://omnitrak/meshes/pinza4_1.stl" scale="0.001 0.001 0.001"/>
    </geometry>
    <material name="silver"/>
  </visual>
  <collision>
    <origin xyz="0.228574 0.297522 0.15124" rpy="0 0 0"/>
    <geometry>
      <mesh filename="package://omnitrak/meshes/pinza4_1.stl" scale="0.001 0.001 0.001"/>
    </geometry>
  </collision>
</link>

<link name="puertafrontal1_1">
  <inertial>
    <origin xyz="0.001999997246981855 1.0520489515664089e-07 0.061743664623073985" rpy="0 0 0"/>
    <mass value="0.16913447733485457"/>
    <inertia ixx="0.001201" iyy="0.000183" izz="0.001019" ixy="-0.0" iyz="0.0" ixz="0.0"/>
  </inertial>
  <visual>
    <origin xyz="-0.275101 0.07984 0.212395" rpy="0 0 0"/>
    <geometry>
      <mesh filename="package://omnitrak/meshes/puertafrontal1_1.stl" scale="0.001 0.001 0.001"/>
    </geometry>
    <material name="silver"/>
  </visual>
  <collision>
    <origin xyz="-0.275101 0.07984 0.212395" rpy="0 0 0"/>
    <geometry>
      <mesh filename="package://omnitrak/meshes/puertafrontal1_1.stl" scale="0.001 0.001 0.001"/>
    </geometry>
  </collision>
</link>

<link name="puertafrontal2_1">
  <inertial>
    <origin xyz="-0.0020000027530206466 1.0520489493459628e-07 0.061743664623073985" rpy="0 0 0"/>
    <mass value="0.16913447733485457"/>
    <inertia ixx="0.001201" iyy="0.000183" izz="0.001019" ixy="-0.0" iyz="0.0" ixz="0.0"/>
  </inertial>
  <visual>
    <origin xyz="0.268399 0.07984 0.212395" rpy="0 0 0"/>
    <geometry>
      <mesh filename="package://omnitrak/meshes/puertafrontal2_1.stl" scale="0.001 0.001 0.001"/>
    </geometry>
    <material name="silver"/>
  </visual>
  <collision>
    <origin xyz="0.268399 0.07984 0.212395" rpy="0 0 0"/>
    <geometry>
      <mesh filename="package://omnitrak/meshes/puertafrontal2_1.stl" scale="0.001 0.001 0.001"/>
    </geometry>
  </collision>
</link>

<link name="wheel1_1">
  <inertial>
    <origin xyz="-0.22818598514842206 -0.32989348193695 -0.24858760961482151" rpy="0 0 0"/>
    <mass value="2.7251757627883464"/>
    <inertia ixx="0.006641" iyy="0.011278" izz="0.006641" ixy="3e-06" iyz="4e-06" ixz="-1e-06"/>
  </inertial>
  <visual>
    <origin xyz="-0.454909 -0.462354 0.017627" rpy="0 0 0"/>
    <geometry>
      <mesh filename="package://omnitrak/meshes/wheel1_1.stl" scale="0.001 0.001 0.001"/>
    </geometry>
    <material name="silver"/>
  </visual>
  <collision>
    <origin xyz="-0.454909 -0.462354 0.017627" rpy="0 0 0"/>
    <geometry>
      <mesh filename="package://omnitrak/meshes/wheel1_1.stl" scale="0.001 0.001 0.001"/>
    </geometry>
  </collision>
</link>

<link name="wheel2_1">
  <inertial>
    <origin xyz="0.2265210135287962 -0.32989348193695256 -0.24858760961481952" rpy="0 0 0"/>
    <mass value="2.7251757627883464"/>
    <inertia ixx="0.006641" iyy="0.011278" izz="0.006641" ixy="3e-06" iyz="4e-06" ixz="-1e-06"/>
  </inertial>
  <visual>
    <origin xyz="0.449685 -0.462354 0.017627" rpy="0 0 0"/>
    <geometry>
      <mesh filename="package://omnitrak/meshes/wheel2_1.stl" scale="0.001 0.001 0.001"/>
    </geometry>
    <material name="silver"/>
  </visual>
  <collision>
    <origin xyz="0.449685 -0.462354 0.017627" rpy="0 0 0"/>
    <geometry>
      <mesh filename="package://omnitrak/meshes/wheel2_1.stl" scale="0.001 0.001 0.001"/>
    </geometry>
  </collision>
</link>

<link name="wheel3_1">
  <inertial>
    <origin xyz="0.2365459809651638 0.3298936923467366 0.30311939038517877" rpy="0 0 0"/>
    <mass value="2.7251757627883464"/>
    <inertia ixx="0.006641" iyy="0.011278" izz="0.006641" ixy="3e-06" iyz="-4e-06" ixz="1e-06"/>
  </inertial>
  <visual>
    <origin xyz="0.00668 0.621834 0.569334" rpy="0 0 0"/>
    <geometry>
      <mesh filename="package://omnitrak/meshes/wheel3_1.stl" scale="0.001 0.001 0.001"/>
    </geometry>
    <material name="silver"/>
  </visual>
  <collision>
    <origin xyz="0.00668 0.621834 0.569334" rpy="0 0 0"/>
    <geometry>
      <mesh filename="package://omnitrak/meshes/wheel3_1.stl" scale="0.001 0.001 0.001"/>
    </geometry>
  </collision>
</link>

<link name="wheel4_1">
  <inertial>
    <origin xyz="-0.21316102035761314 0.32989369234673704 0.3031193903851791" rpy="0 0 0"/>
    <mass value="2.7251757627883464"/>
    <inertia ixx="0.006641" iyy="0.011278" izz="0.006641" ixy="3e-06" iyz="-4e-06" ixz="1e-06"/>
  </inertial>
  <visual>
    <origin xyz="0.00668 0.621834 0.569334" rpy="0 0 0"/>
    <geometry>
      <mesh filename="package://omnitrak/meshes/wheel4_1.stl" scale="0.001 0.001 0.001"/>
    </geometry>
    <material name="silver"/>
  </visual>
  <collision>
    <origin xyz="0.00668 0.621834 0.569334" rpy="0 0 0"/>
    <geometry>
      <mesh filename="package://omnitrak/meshes/wheel4_1.stl" scale="0.001 0.001 0.001"/>
    </geometry>
  </collision>
</link>

<link name="casing1_1">
  <inertial>
    <origin xyz="-0.1764458205511993 0.353214946163923 0.1373482606199878" rpy="0 0 0"/>
    <mass value="0.12373722026170184"/>
    <inertia ixx="0.000185" iyy="0.000637" izz="0.000545" ixy="4e-06" iyz="-7e-06" ixz="2.4e-05"/>
  </inertial>
  <visual>
    <origin xyz="-0.395125 0.66061 0.202781" rpy="0 0 0"/>
    <geometry>
      <mesh filename="package://omnitrak/meshes/casing1_1.stl" scale="0.001 0.001 0.001"/>
    </geometry>
    <material name="silver"/>
  </visual>
  <collision>
    <origin xyz="-0.395125 0.66061 0.202781" rpy="0 0 0"/>
    <geometry>
      <mesh filename="package://omnitrak/meshes/casing1_1.stl" scale="0.001 0.001 0.001"/>
    </geometry>
  </collision>
</link>

<link name="casing2_1">
  <inertial>
    <origin xyz="0.16974381504516176 -0.19373473575413852 0.13734826061998928" rpy="0 0 0"/>
    <mass value="0.12373722026170184"/>
    <inertia ixx="0.000185" iyy="0.000637" izz="0.000545" ixy="4e-06" iyz="7e-06" ixz="-2.4e-05"/>
  </inertial>
  <visual>
    <origin xyz="0.381721 -0.34165 0.202781" rpy="0 0 0"/>
    <geometry>
      <mesh filename="package://omnitrak/meshes/casing2_1.stl" scale="0.001 0.001 0.001"/>
    </geometry>
    <material name="silver"/>
  </visual>
  <collision>
    <origin xyz="0.381721 -0.34165 0.202781" rpy="0 0 0"/>
    <geometry>
      <mesh filename="package://omnitrak/meshes/casing2_1.stl" scale="0.001 0.001 0.001"/>
    </geometry>
  </collision>
</link>

<link name="casing3_1">
  <inertial>
    <origin xyz="0.1712286896441423 0.3479681861241731 0.14221600428045722" rpy="0 0 0"/>
    <mass value="0.21325351995867553"/>
    <inertia ixx="0.000344" iyy="0.00093" izz="0.000854" ixy="-6e-06" iyz="-2.8e-05" ixz="-3.9e-05"/>
  </inertial>
  <visual>
    <origin xyz="0.381721 0.66061 0.202781" rpy="0 0 0"/>
    <geometry>
      <mesh filename="package://omnitrak/meshes/casing3_1.stl" scale="0.001 0.001 0.001"/>
    </geometry>
    <material name="silver"/>
  </visual>
  <collision>
    <origin xyz="0.381721 0.66061 0.202781" rpy="0 0 0"/>
    <geometry>
      <mesh filename="package://omnitrak/meshes/casing3_1.stl" scale="0.001 0.001 0.001"/>
    </geometry>
  </collision>
</link>

<link name="casing4_1">
  <inertial>
    <origin xyz="-0.17793069515017707 -0.18848797571438533 0.14221600428045666" rpy="0 0 0"/>
    <mass value="0.21325351995867553"/>
    <inertia ixx="0.000344" iyy="0.00093" izz="0.000854" ixy="-6e-06" iyz="2.8e-05" ixz="3.9e-05"/>
  </inertial>
  <visual>
    <origin xyz="-0.395125 -0.34165 0.202781" rpy="0 0 0"/>
    <geometry>
      <mesh filename="package://omnitrak/meshes/casing4_1.stl" scale="0.001 0.001 0.001"/>
    </geometry>
    <material name="silver"/>
  </visual>
  <collision>
    <origin xyz="-0.395125 -0.34165 0.202781" rpy="0 0 0"/>
    <geometry>
      <mesh filename="package://omnitrak/meshes/casing4_1.stl" scale="0.001 0.001 0.001"/>
    </geometry>
  </collision>
</link>

<joint name="Rigid1" type="fixed">
  <origin xyz="0.003351 0.081985 -0.083653" rpy="0 0 0"/>
  <parent link="base_link"/>
  <child link="perfillateral1_1"/>
</joint>

<joint name="Rigid2" type="fixed">
  <origin xyz="0.003351 -0.241665 -0.083653" rpy="0 0 0"/>
  <parent link="base_link"/>
  <child link="perfillateral2_1"/>
</joint>

<joint name="Rigid3" type="fixed">
  <origin xyz="0.367747 -0.271665 -0.275101" rpy="0 0 0"/>
  <parent link="perfillateral2_1"/>
  <child link="tapabase1_1"/>
</joint>

<joint name="Rigid4" type="fixed">
  <origin xyz="-0.367747 0.111985 0.275101" rpy="0 0 0"/>
  <parent link="perfillateral1_1"/>
  <child link="tapabase2_1"/>
</joint>

<joint name="Rigid5" type="fixed">
  <origin xyz="-0.367747 0.111985 -0.268399" rpy="0 0 0"/>
  <parent link="perfillateral1_1"/>
  <child link="tapabase3_1"/>
</joint>

<joint name="Rigid6" type="fixed">
  <origin xyz="0.367747 -0.271665 0.268399" rpy="0 0 0"/>
  <parent link="perfillateral2_1"/>
  <child link="tapabase4_1"/>
</joint>

<joint name="Rigid7" type="fixed">
  <origin xyz="0.191994 -0.15452 -0.02945" rpy="0 0 0"/>
  <parent link="tapabase3_1"/>
  <child link="perfilfrontal1_1"/>
</joint>

<joint name="Rigid8" type="fixed">
  <origin xyz="-0.191994 0.03945 0.579652" rpy="0 0 0"/>
  <parent link="tapabase1_1"/>
  <child link="perfilfrontal2_1"/>
</joint>

<joint name="Rigid10" type="fixed">
  <origin xyz="-0.205287 0.139082 -0.008781" rpy="0 0 0"/>
  <parent link="perfilfrontal1_1"/>
  <child link="plataforma_1"/>
</joint>

<joint name="Rigid11" type="fixed">
  <origin xyz="0.565659 -0.099047 0.33863" rpy="0 0 0"/>
  <parent link="plataforma_1"/>
  <child link="esquinerasuperior1_1"/>
</joint>

<joint name="Rigid12" type="fixed">
  <origin xyz="0.196459 -0.417697 0.33863" rpy="0 0 0"/>
  <parent link="plataforma_1"/>
  <child link="esquinerasuperior2_1"/>
</joint>

<joint name="Rigid13" type="fixed">
  <origin xyz="0.196459 -0.099047 0.33863" rpy="0 0 0"/>
  <parent link="plataforma_1"/>
  <child link="esquinerasuperior3_1"/>
</joint>

<joint name="Rigid14" type="fixed">
  <origin xyz="0.565659 -0.417697 0.33863" rpy="0 0 0"/>
  <parent link="plataforma_1"/>
  <child link="esquinerasuperior4_1"/>
</joint>

<joint name="Rigid15" type="fixed">
  <origin xyz="0.632259 -0.258372 0.33963" rpy="0 0 0"/>
  <parent link="plataforma_1"/>
  <child link="escotilla_1"/>
</joint>

<joint name="Rigid16" type="fixed">
  <origin xyz="-0.665306 0.260306 -0.298399" rpy="0 0 0"/>
  <parent link="tapabase4_1"/>
  <child link="esquinera1_1"/>
</joint>

<joint name="Rigid17" type="fixed">
  <origin xyz="0.070188 -0.100626 0.238399" rpy="0 0 0"/>
  <parent link="tapabase3_1"/>
  <child link="esquinera2_1"/>
</joint>

<joint name="Rigid18" type="fixed">
  <origin xyz="0.665306 -0.100626 -0.305101" rpy="0 0 0"/>
  <parent link="tapabase2_1"/>
  <child link="esquinera3_1"/>
</joint>

<joint name="Rigid19" type="fixed">
  <origin xyz="-0.070188 0.260306 0.245101" rpy="0 0 0"/>
  <parent link="tapabase1_1"/>
  <child link="esquinera4_1"/>
</joint>

<joint name="Rigid22" type="fixed">
  <origin xyz="-0.115158 -0.22471 -0.096838" rpy="0 0 0"/>
  <parent link="esquinera3_1"/>
  <child link="baseps1_1"/>
</joint>

<joint name="Rigid23" type="fixed">
  <origin xyz="-0.224997 -0.115158 -0.096838" rpy="0 0 0"/>
  <parent link="esquinera2_1"/>
  <child link="baseps2_1"/>
</joint>

<joint name="Rigid24" type="fixed">
  <origin xyz="-0.115158 0.22471 -0.261518" rpy="0 0 0"/>
  <parent link="esquinera4_1"/>
  <child link="baseps3_1"/>
</joint>

<joint name="Rigid25" type="fixed">
  <origin xyz="-0.224997 0.115159 -0.261518" rpy="0 0 0"/>
  <parent link="esquinera1_1"/>
  <child link="baseps4_1"/>
</joint>

<joint name="Rigid26" type="fixed">
  <origin xyz="0.297702 -0.136728 0.311618" rpy="0 0 0"/>
  <parent link="baseps4_1"/>
  <child link="mediahoja1_1"/>
</joint>

<joint name="Rigid27" type="fixed">
  <origin xyz="0.042452 -0.246279 0.311618" rpy="0 0 0"/>
  <parent link="baseps3_1"/>
  <child link="mediahoja2_1"/>
</joint>

<joint name="Rigid28" type="fixed">
  <origin xyz="0.297702 0.136928 0.146938" rpy="0 0 0"/>
  <parent link="baseps2_1"/>
  <child link="mediahoja3_1"/>
</joint>

<joint name="Rigid29" type="fixed">
  <origin xyz="0.042452 0.24648 0.146938" rpy="0 0 0"/>
  <parent link="baseps1_1"/>
  <child link="mediahoja4_1"/>
</joint>

<joint name="Rigid30" type="fixed">
  <origin xyz="0.030642 -0.055712 -0.045337" rpy="0 0 0"/>
  <parent link="mediahoja1_1"/>
  <child link="soportemotorsito1_1"/>
</joint>

<joint name="Rigid31" type="fixed">
  <origin xyz="-0.030641 -0.055712 -0.045337" rpy="0 0 0"/>
  <parent link="mediahoja2_1"/>
  <child link="soportemotorsito2_1"/>
</joint>

<joint name="Rigid32" type="fixed">
  <origin xyz="0.030642 0.055711 -0.045337" rpy="0 0 0"/>
  <parent link="mediahoja3_1"/>
  <child link="soportemotorsito3_1"/>
</joint>

<joint name="Rigid33" type="fixed">
  <origin xyz="-0.030641 0.055711 -0.045337" rpy="0 0 0"/>
  <parent link="mediahoja4_1"/>
  <child link="soportemotorsito4_1"/>
</joint>

<joint name="Rigid34" type="fixed">
  <origin xyz="0.0 0.0 0.03" rpy="0 0 0"/>
  <parent link="soportemotorsito3_1"/>
  <child link="apoyomotor1_1"/>
</joint>

<joint name="Rigid35" type="fixed">
  <origin xyz="0.0 0.0 0.03" rpy="0 0 0"/>
  <parent link="soportemotorsito1_1"/>
  <child link="apoyomotor2_1"/>
</joint>

<joint name="Rigid36" type="fixed">
  <origin xyz="0.0 0.0 0.03" rpy="0 0 0"/>
  <parent link="soportemotorsito2_1"/>
  <child link="apoyomotor3_1"/>
</joint>

<joint name="Rigid37" type="fixed">
  <origin xyz="0.0 0.0 0.03" rpy="0 0 0"/>
  <parent link="soportemotorsito4_1"/>
  <child link="apoyomotor4_1"/>
</joint>

<joint name="Rigid38" type="fixed">
  <origin xyz="-0.030642 -0.025711 0.003175" rpy="0 0 0"/>
  <parent link="apoyomotor1_1"/>
  <child link="motor1_1"/>
</joint>

<joint name="Rigid39" type="fixed">
  <origin xyz="-0.030642 0.025712 0.003175" rpy="0 0 0"/>
  <parent link="apoyomotor2_1"/>
  <child link="motor2_1"/>
</joint>

<joint name="Rigid40" type="fixed">
  <origin xyz="0.030641 0.025712 0.003175" rpy="0 0 0"/>
  <parent link="apoyomotor3_1"/>
  <child link="motor3_1"/>
</joint>

<joint name="Rigid41" type="fixed">
  <origin xyz="0.030641 -0.025711 0.003175" rpy="0 0 0"/>
  <parent link="apoyomotor4_1"/>
  <child link="motor4_1"/>
</joint>

<joint name="Rev42" type="continuous">
  <origin xyz="0.0 0.0 0.0" rpy="0 0 0"/>
  <parent link="motor1_1"/>
  <child link="acoplerigido1_1"/>
  <axis xyz="-0.0 -0.0 1.0"/>
</joint>

<joint name="Rev43" type="continuous">
  <origin xyz="0.0 0.0 0.0" rpy="0 0 0"/>
  <parent link="motor2_1"/>
  <child link="acoplerigido2_1"/>
  <axis xyz="0.0 0.0 1.0"/>
</joint>

<joint name="Rev44" type="continuous">
  <origin xyz="0.0 0.0 0.0" rpy="0 0 0"/>
  <parent link="motor3_1"/>
  <child link="acoplerigido3_1"/>
  <axis xyz="-0.0 0.0 1.0"/>
</joint>

<joint name="Rev45" type="continuous">
  <origin xyz="0.0 0.0 0.0" rpy="0 0 0"/>
  <parent link="motor4_1"/>
  <child link="acoplerigido4_1"/>
  <axis xyz="0.0 -0.0 1.0"/>
</joint>

<joint name="Rigid46" type="fixed">
  <origin xyz="0.228205 0.145113 -0.125716" rpy="0 0 0"/>
  <parent link="acoplerigido4_1"/>
  <child link="acopledeleje1_1"/>
</joint>

<joint name="Rigid47" type="fixed">
  <origin xyz="-0.221502 0.145113 -0.125716" rpy="0 0 0"/>
  <parent link="acoplerigido1_1"/>
  <child link="acopledeleje2_1"/>
</joint>

<joint name="Rigid48" type="fixed">
  <origin xyz="-0.221502 -0.304594 -0.125716" rpy="0 0 0"/>
  <parent link="acoplerigido2_1"/>
  <child link="acopledeleje3_1"/>
</joint>

<joint name="Rigid49" type="fixed">
  <origin xyz="0.228205 -0.304594 -0.125716" rpy="0 0 0"/>
  <parent link="acoplerigido3_1"/>
  <child link="acopledeleje4_1"/>
</joint>

<joint name="Rigid50" type="fixed">
  <origin xyz="-0.228205 -0.145113 0.050191" rpy="0 0 0"/>
  <parent link="acopledeleje1_1"/>
  <child link="flange1_1"/>
</joint>

<joint name="Rigid51" type="fixed">
  <origin xyz="0.221502 -0.145113 0.050191" rpy="0 0 0"/>
  <parent link="acopledeleje2_1"/>
  <child link="flange2_1"/>
</joint>

<joint name="Rigid52" type="fixed">
  <origin xyz="-0.228205 0.304594 0.050191" rpy="0 0 0"/>
  <parent link="acopledeleje4_1"/>
  <child link="flange3_1"/>
</joint>

<joint name="Rigid53" type="fixed">
  <origin xyz="0.221502 0.304594 0.050191" rpy="0 0 0"/>
  <parent link="acopledeleje3_1"/>
  <child link="flange4_1"/>
</joint>

<joint name="Rigid54" type="fixed">
  <origin xyz="-0.007071 -0.007072 0.0" rpy="0 0 0"/>
  <parent link="flange2_1"/>
  <child link="pinza1_1"/>
</joint>

<joint name="Rigid55" type="fixed">
  <origin xyz="-0.007071 -0.007072 0.0" rpy="0 0 0"/>
  <parent link="flange1_1"/>
  <child link="pinza2_1"/>
</joint>

<joint name="Rigid56" type="fixed">
  <origin xyz="-0.007071 0.007071 0.0" rpy="0 0 0"/>
  <parent link="flange3_1"/>
  <child link="pinza3_1"/>
</joint>

<joint name="Rigid57" type="fixed">
  <origin xyz="-0.007071 0.007071 0.0" rpy="0 0 0"/>
  <parent link="flange4_1"/>
  <child link="pinza4_1"/>
</joint>

<joint name="Rigid58" type="fixed">
  <origin xyz="0.275101 -0.07984 -0.212395" rpy="0 0 0"/>
  <parent link="base_link"/>
  <child link="puertafrontal1_1"/>
</joint>

<joint name="Rigid59" type="fixed">
  <origin xyz="-0.268399 -0.07984 -0.212395" rpy="0 0 0"/>
  <parent link="base_link"/>
  <child link="puertafrontal2_1"/>
</joint>

<joint name="Rev60" type="continuous">
  <origin xyz="0.233776 0.324312 0.133613" rpy="0 0 0"/>
  <parent link="pinza2_1"/>
  <child link="wheel1_1"/>
  <axis xyz="-0.0 -1.0 -0.0"/>
</joint>

<joint name="Rev61" type="continuous">
  <origin xyz="-0.221111 0.324312 0.133613" rpy="0 0 0"/>
  <parent link="pinza1_1"/>
  <child link="wheel2_1"/>
  <axis xyz="0.0 -1.0 -0.0"/>
</joint>

<joint name="Rev62" type="continuous">
  <origin xyz="-0.227813 -0.324312 -0.418094" rpy="0 0 0"/>
  <parent link="pinza3_1"/>
  <child link="wheel3_1"/>
  <axis xyz="0.0 1.0 -0.0"/>
</joint>

<joint name="Rev63" type="continuous">
  <origin xyz="0.221894 -0.324312 -0.418094" rpy="0 0 0"/>
  <parent link="pinza4_1"/>
  <child link="wheel4_1"/>
  <axis xyz="-0.0 1.0 -0.0"/>
</joint>

<joint name="Rigid64" type="fixed">
  <origin xyz="0.197562 -0.330305 -0.093891" rpy="0 0 0"/>
  <parent link="soportemotorsito2_1"/>
  <child link="casing1_1"/>
</joint>

<joint name="Rigid65" type="fixed">
  <origin xyz="-0.19086 0.170825 -0.093891" rpy="0 0 0"/>
  <parent link="soportemotorsito3_1"/>
  <child link="casing2_1"/>
</joint>

<joint name="Rigid66" type="fixed">
  <origin xyz="-0.19086 -0.330305 -0.093891" rpy="0 0 0"/>
  <parent link="soportemotorsito1_1"/>
  <child link="casing3_1"/>
</joint>

<joint name="Rigid67" type="fixed">
  <origin xyz="0.197562 0.170825 -0.093891" rpy="0 0 0"/>
  <parent link="soportemotorsito4_1"/>
  <child link="casing4_1"/>
</joint>

</robot>
